<?xml version='1.0' encoding='utf-8'?>

<robot xmlns:xacro="http://www.ros.org/wiki/xacro" name="cocoa">
    <!-- add more codes -->
    <material name="Grey">
        <color rgba="0.2 0.2 0.2 1.0"/>
    </material>
      
    <material name="Orange">
        <color rgba="1.0 0.423529411765 0.0392156862745 1.0"/>
    </material>
      
    <material name="Blue">
        <color rgba="0.5 0.7 1.0 1.0"/>      
    </material>

    <link name="base_link">
        <visual>
          <origin rpy="0 0 0" xyz="0 0 0"/>
          <geometry>
            <mesh filename="package://cocoa_description/meshes/base_link.stl"/>
          </geometry>
          <material name="Grey"/>
        </visual>
      </link>
    
    <joint name="joint_rev_b_0" type="revolute">
        <parent link="base_link"/>
        <child link="link_0"/>
        <origin rpy="0 0 0" xyz="0 0 0.14"/>
        <axis xyz="0 0 1"/>
        <limit lower="-3.14" upper="3.14" effort="0.5" velocity="0.5"/>
    </joint>

    <link name="link_0">
        <visual>
          <origin rpy="0 0 0" xyz="0 0 0"/>
          <geometry>
            <mesh filename="package://cocoa_description/meshes/link_0.stl"/>
          </geometry>
          <material name="Grey"/>
        </visual>
      </link>

    <joint name="joint_rev_0_1" type="revolute">
        <parent link="link_0"/>
        <child link="link_1"/>
        <origin rpy="1.5708 0 1.5708" xyz="0 0 0"/>
        <axis xyz="0 0 1"/>
        <limit lower="-0.523" upper="0.523" effort="0.5" velocity="0.5"/>
    </joint>

    <link name="link_1">
        <visual>
          <origin rpy="0 0 0" xyz="0 0 0"/>
          <geometry>
            <mesh filename="package://cocoa_description/meshes/link_1.stl"/>
          </geometry>
          <material name="Grey"/>
        </visual>
      </link>
    
    <joint name="joint_rev_1_2" type="revolute">
        <parent link="link_1"/>
        <child link="link_2"/>
        <origin rpy="0 0 0" xyz="0.262 0 0"/>
        <axis xyz="0 0 1"/>
        <limit lower="-1.0472" upper="1.5708" effort="0.5" velocity="0.5"/>
    </joint>

    <link name="link_2">
        <visual>
          <origin rpy="0 0 0" xyz="0 0 0"/>
          <geometry>
            <mesh filename="package://cocoa_description/meshes/link_2.stl"/>
          </geometry>
          <material name="Grey"/>
        </visual>
      </link>
    
    <joint name="joint_pris_2_3" type="prismatic">
        <parent link="link_2"/>
        <child link="link_3"/>
        <origin rpy="1.5708 0 0" xyz="0.0605 0 0.062"/>
        <!-- <origin rpy="1.5708 0 0" xyz="0.0605 0 0"/> -->
        <axis xyz="0 0 1"/>
        <limit lower="0" upper="0.134" effort="0.5" velocity="0.5"/>
    </joint>

    <link name="link_3">
        <visual>
          <origin rpy="0 0 0" xyz="0 0 0"/>
          <geometry>
            <mesh filename="package://cocoa_description/meshes/link_3.stl"/>
          </geometry>
          <material name="Grey"/>
        </visual>
      </link>

    <joint name="joint_eff" type="fixed">
        <parent link="link_3"/>
        <child link="end_effector"/>
        <origin rpy="1.57 0 -1.57" xyz="-0.03 0 0.0282"/>
        <axis xyz="0 0 1"/>
    </joint>

    <link name="end_effector">
        <visual>
          <origin rpy="0 0 0" xyz="0 0 0"/>
          <geometry>
            <mesh filename="package://cocoa_description/meshes/end_effector.stl"/>
          </geometry>
          <material name="Grey"/>
        </visual>
      </link>

</robot>
